<?xml version="1.0" ?>
<!--Autogenerated by "taco/models/sdf2urdf" converter from "../kuka_iiwa/kuka_iiwa.sdf"-->
<robot name="kuka_iiwa">

    <!-- GROUND LINK -->
  <link name ="ground_link">
    <inertial>
      <origin xyz="0.0 0.0 0.0" rpy="0 0 0" />
      <mass value="0.001" />
      <inertia ixx="1E-06" ixy="0.0" ixz="0.0" iyy="1E-06" iyz="0.0" izz="1E-06" />
    </inertial>
  </link>


  <!-- MOBILE BASE LINKS -->
  <link name ="base_x">
    <inertial>
      <origin xyz="0.0 0.0 0.0" rpy="0 0 0" />
      <mass value="0.001" />
      <inertia ixx="1E-06" ixy="0.0" ixz="0.0" iyy="1E-06" iyz="0.0" izz="1E-06" />
    </inertial>
  </link>

  <link name = "base_y">
    <inertial>
      <origin xyz="0.0 0.0 0.0" rpy="0 0 0" />
      <mass value = "0.001" />
      <inertia ixx="1E-06" ixy="0.0" ixz="0.0" iyy="1E-06" iyz="0.0" izz="1E-06" />
    </inertial>
  </link>

  <!-- MOBILE BASE -->
  <link name = "mobile_base">
    <inertial>
      <origin xyz="0.0 0.0 0.1757" rpy="0 0 0" />
      <mass value = "64.6" />
      <inertia ixx="1.721" ixy="0.0" ixz="0.0" iyy="1.712" iyz="0.0" izz="2.030" />
    </inertial>
    <visual>
      <geometry>
        <mesh filename="../../../model/iiwa7/meshes/kuka_mobile_base.obj" />
      </geometry>
    </visual>
  </link>

    <link name="base_link">
        <inertial>
            <origin xyz="0 0 0.14" rpy="0 -0 0" />
            <mass value="4" />
            <inertia ixx="0.4" iyy="0.4" izz="0.4" ixy="0" ixz="0" iyz="0" />
        </inertial>
        <visual>
            <origin xyz="0 0 0" rpy="0 -0 0" />
            <geometry>
                <mesh filename="../../../model/iiwa7/meshes/base.obj" scale="1 1 1" />
            </geometry>
        </visual>
        <!-- <collision>
            <origin xyz="0 0 0" rpy="0 -0 0" />
            <geometry>
                <mesh filename="../../../model/iiwa7/meshes/base.obj" scale="1 1 1" />
            </geometry>
        </collision> -->
    </link>
    <link name="link0">
        <inertial>
            <origin xyz="0 0 0.14" rpy="0 -0 0" />
            <mass value="4" />
            <inertia ixx="0.4" iyy="0.4" izz="0.4" ixy="0" ixz="0" iyz="0" />
        </inertial>
        <visual>
            <origin xyz="0 0 0" rpy="0 -0 0" />
            <geometry>
                <mesh filename="../../../model/iiwa7/meshes/link0.obj" scale="1 1 1" />
            </geometry>
        </visual>
        <!-- <collision>
            <origin xyz="0 0 0" rpy="0 -0 0" />
            <geometry>
                <mesh filename="../../../model/iiwa7/meshes/link0.obj" scale="1 1 1" />
            </geometry>
        </collision> -->
    </link>
    <link name="link1">
        <inertial>
            <origin xyz="0 0 0.14" rpy="0 -0 0" />
            <mass value="4" />
            <inertia ixx="0.4" iyy="0.4" izz="0.4" ixy="0" ixz="0" iyz="0" />
        </inertial>
        <visual>
            <origin xyz="0 0 0" rpy="0 -0 0" />
            <geometry>
                <mesh filename="../../../model/iiwa7/meshes/link1.obj" scale="1 1 1" />
            </geometry>
        </visual>
        <!-- <collision>
            <origin xyz="0 0 0" rpy="0 -0 0" />
            <geometry>
                <mesh filename="../../../model/iiwa7/meshes/link1.obj" scale="1 1 1" />
            </geometry>
        </collision> -->
    </link>
    <link name="link2">
        <inertial>
            <origin xyz="0 0 0.14" rpy="0 -0 0" />
            <mass value="4" />
            <inertia ixx="0.4" iyy="0.4" izz="0.4" ixy="0" ixz="0" iyz="0" />
        </inertial>
        <visual>
            <origin xyz="0 0 0" rpy="0 -0 0" />
            <geometry>
                <mesh filename="../../../model/iiwa7/meshes/link2.obj" scale="1 1 1" />
            </geometry>
        </visual>
        <!-- <collision>
            <origin xyz="0 0 0" rpy="0 -0 0" />
            <geometry>
                <mesh filename="../../../model/iiwa7/meshes/link2.obj" scale="1 1 1" />
            </geometry>
        </collision> -->
    </link>
    <link name="link3">
        <inertial>
            <origin xyz="0 0 0.14" rpy="0 0 0" />
            <mass value="4" />
            <inertia ixx="0.4" iyy="0.4" izz="0.4" ixy="0" ixz="0" iyz="0" />
        </inertial>
        <visual>
            <origin xyz="0 0 0" rpy="0 0 3.1415926535897" />
            <geometry>
                <mesh filename="../../../model/iiwa7/meshes/link3.obj" scale="1 1 1" />
            </geometry>
        </visual>
        <!-- <collision>
            <origin xyz="0 0 0" rpy="0 -0 0" />
            <geometry>
                <mesh filename="../../../model/iiwa7/meshes/link3.obj" scale="1 1 1" />
            </geometry>
        </collision> -->
    </link>
    <link name="link4">
        <inertial>
            <origin xyz="0 0 0.14" rpy="0 0 0" />
            <mass value="3" />
            <inertia ixx="0.3" iyy="0.3" izz="0.3" ixy="0" ixz="0" iyz="0" />
        </inertial>
        <visual>
            <origin xyz="0 0 0" rpy="0 0 0" />
            <geometry>
                <mesh filename="../../../model/iiwa7/meshes/link4.obj" scale="1 1 1" />
            </geometry>
        </visual>
        <!-- <collision>
            <origin xyz="0 0 0" rpy="0 -0 0" />
            <geometry>
                <mesh filename="../../../model/iiwa7/meshes/link4.obj" scale="1 1 1" />
            </geometry>
        </collision> -->
    </link>
    <link name="link5">
        <inertial>
            <origin xyz="0 0 0.14" rpy="0 0 0" />
            <mass value="2" />
            <inertia ixx="0.2" iyy="0.2" izz="0.2" ixy="0" ixz="0" iyz="0" />
        </inertial>
        <visual>
            <origin xyz="0 -0.06 0" rpy="0 0 0" />
            <geometry>
                <mesh filename="../../../model/iiwa7/meshes/link5.obj" scale="1 1 1" />
            </geometry>
        </visual>
        <!-- <collision>
            <origin xyz="0 -0.06 0" rpy="0 -0 0" />
            <geometry>
                <mesh filename="../../../model/iiwa7/meshes/link5.obj" scale="1 1 1" />
            </geometry>
        </collision> -->
    </link>
    <link name="link6">
        <inertial>
            <origin xyz="0 0 0.03" rpy="0 0 0" />
            <mass value="1" />
            <inertia ixx="0.1" iyy="0.1" izz="0.1" ixy="0" ixz="0" iyz="0" />
        </inertial>
        <visual>
            <origin xyz="0 0 0" rpy="0 0 0" />
            <geometry>
                <mesh filename="../../../model/iiwa7/meshes/link6.obj" scale="1 1 1" />
            </geometry>
        </visual>
        <!-- <collision>
            <origin xyz="0 0 0" rpy="0 0 0" />
            <geometry>
                <mesh filename="../../../model/iiwa7/meshes/link6.obj" scale="1 1 1" />
            </geometry>
        </collision> -->
        <visual>
        <origin xyz="0 0 0.03" rpy="0 0 0" />
        <geometry>
          <mesh filename="../../../model/iiwa7/meshes/hand.obj" scale="1 1 1"/>
        </geometry>
      </visual>
    </link>

    <link name="leftfinger">
      <inertial>
        <origin xyz="0 0 0.03" rpy="0 -0 0" />
        <mass value="0.1" />
        <inertia ixx="0.01" iyy="0.01" izz="0.005" ixy="0" ixz="0" iyz="0" />
      </inertial>
      <visual>
        <geometry>
          <mesh filename="../../../model/iiwa7/meshes/finger.obj"/>
        </geometry>
      </visual>

        <visual>
        <origin xyz="0 .01 0" rpy="0 0 0" />
        <geometry>
          <box size="0.03 .02 0.1" />
        </geometry>
      </visual> 
    </link>

    <link name="rightfinger">
      <inertial>
        <origin xyz="0 0 0.03" rpy="0 -0 0" />
        <mass value="0.1" />
        <inertia ixx="0.01" iyy="0.01" izz="0.005" ixy="0" ixz="0" iyz="0" />
      </inertial>
      <visual>
        <!-- <origin xyz="0 0 0" rpy="0 0 3.14159265359" /> -->
        <geometry>
          <mesh filename="../../../model/iiwa7/meshes/finger.obj"/>
        </geometry>
      </visual>

        <visual>
        <origin xyz="0 .01 0" rpy="0 0 0" />
        <geometry>
          <box size="0.03 .02 0.1" />
        </geometry>
      </visual> 
    </link>
  

    <joint name = "base_prismatic_x" type = "prismatic">
    <origin xyz = "0 0 0" rpy = "0 0 0"/> 
    <parent link = "ground_link" />
    <child link= "base_x"/>
    <axis xyz = "1 0 0" />
    <limit effort="87" lower="-2.8973" upper="2.9873" velocity="2.1750" />
  </joint>

  <joint name = "base_prismatic_y" type = "prismatic">
    <origin xyz = "0 0 0" rpy = "0 0 0"/> 
    <parent link = "base_x" />
    <child link= "base_y"/>
    <axis xyz = "0 1 0" />
    <limit effort="87" lower="-2.8973" upper="2.9873" velocity="2.1750" />
  </joint>

  <joint name = "base_revolute" type = "revolute">
    <origin xyz = "0 0 0.0" rpy = "0 0 0"/> 
    <parent link = "base_y" />
    <child link= "mobile_base"/>
    <axis xyz = "0 0 1" />
    <limit effort="87" lower="-2.8973" upper="2.8973" velocity="2.1750" />
  </joint>

   <joint name = "base_arm_fixed" type = "fixed">
    <origin xyz = "0 0 0.125" rpy = "0 0 0"/> 
    <parent link = "mobile_base" />
    <child link= "base_link"/>
    <axis xyz = "0 0 1" />
    <limit effort="87" lower="-2.8973" upper="2.8973" velocity="2.1750" />
  </joint>

  <!-- <joint name = "base_prismatic_link0" type = "prismatic">
    <origin xyz = "0 0 0.33" rpy = "0 0 0"/> 
    <parent link = "base_link" />
    <child link= "link0"/>
    <axis xyz = "0 0 1" />
    <limit effort="87" lower="-2.8973" upper="2.8973" velocity="2.1750" />
  </joint> -->

    <joint name="j0" type="revolute">
        <parent link="base_link" />
        <child link="link0" />
        <origin xyz="0.000000 0.000000 0.155767" rpy="0.000000 0.000000 0.000000" />
        <axis xyz="0 0 1" />
        <limit lower="-2.967" upper="2.967" effort="176" velocity="1.7104" />
    </joint>
    <joint name="j1" type="revolute">
        <parent link="link0" />
        <child link="link1" />
        <origin xyz="0.000000 0.000000 0.182500" rpy="0.000000 0.000000 0.000000" />
        <axis xyz="0 1 0" />
        <limit lower="-2.0944" upper="2.0944" effort="176" velocity="1.7104" />
    </joint>
    <joint name="j2" type="revolute">
        <parent link="link1" />
        <child link="link2" />
        <origin xyz="0.000000 0.000000 0.185000" rpy="0.000000 0.000000 0.000000" />
        <axis xyz="0 0 1" />
        <limit lower="-2.967" upper="2.967" effort="110" velocity="1.7453" />
    </joint>
    <joint name="j3" type="revolute">
        <parent link="link2" />
        <child link="link3" />
        <origin xyz="0.000000 0.000000 0.217000" rpy="0.000000 0.000000 3.1415926535897" />
        <axis xyz="0 1 0" />
        <limit lower="-2.0944" upper="2.0944" effort="110" velocity="2.2689" />
    </joint>
    <joint name="j4" type="revolute">
        <parent link="link3" />
        <child link="link4" />
        <origin xyz="0.000000 0.000000 0.186000" rpy="0.000000 0.000000 -3.1415926535897" />
        <axis xyz="0 0 1" />
        <limit lower="-2.967" upper="2.967" effort="110" velocity="2.4434" />
    </joint>
    <joint name="j5" type="revolute">
        <parent link="link4" />
        <child link="link5" />
        <origin xyz="0.000000 0.000000 0.217003" rpy="0.000000 0.000000 0.000000" />
        <axis xyz="0 1 0" />
        <limit lower="-2.0944" upper="2.0944" effort="40" velocity="3.1416" />
    </joint>
    <joint name="j6" type="revolute">
        <parent link="link5" />
        <child link="link6" />
        <origin xyz="0.000000 0.000000 0.081000" rpy="0.000000 0.000000 0.000000" />
        <axis xyz="0 0 1" />
        <limit lower="-3.0543" upper="3.0543" effort="40" velocity="3.1416" />
    </joint>

    <joint name="finger_joint1" type="prismatic">
      <parent link="link6"/>
      <child link="leftfinger"/>
      <origin xyz="-0.015 0.04 0.09" rpy="0 0 1.570796327"/>
      <axis xyz="0 1 0"/>
      <!-- <calibration rising="0.02" /> -->
      <limit effort="20" lower="0.0" upper="0.04" velocity="0.2"/>
    </joint>

    <joint name="finger_joint2" type="prismatic">
      <parent link="link6"/>
      <child link="rightfinger"/>
      <origin xyz="0.015 0.04 0.09" rpy="0 0 -1.570796327"/>
      <axis xyz="0 1 0"/>
      <!-- <calibration rising="-0.04" /> -->
      <limit effort="20" lower="0.0" upper="0.04" velocity="0.2"/>
      <!-- <mimic joint="finger_joint1" /> -->
    </joint>

</robot>
